
/home/pi/fishtank/   ***using directory***

'sjenkins'
'5e26e35fdb1244fa6ed34aeaf9ca38f6ed2ff068'
'upfishtemp'
Traceback (most recent call last):
  File "/usr/lib/python3/dist-packages/urllib3/connectionpool.py", line 516, in urlopen
    body=body, headers=headers)
  File "/usr/lib/python3/dist-packages/urllib3/connectionpool.py", line 304, in _make_request
    self._validate_conn(conn)
  File "/usr/lib/python3/dist-packages/urllib3/connectionpool.py", line 724, in _validate_conn
    conn.connect()
  File "/usr/lib/python3/dist-packages/urllib3/connection.py", line 203, in connect
    conn = self._new_conn()
  File "/usr/lib/python3/dist-packages/urllib3/connection.py", line 133, in _new_conn
    (self.host, self.port), self.timeout, **extra_kw)
  File "/usr/lib/python3/dist-packages/urllib3/util/connection.py", line 64, in create_connection
    for res in socket.getaddrinfo(host, port, 0, socket.SOCK_STREAM):
  File "/usr/lib/python3.4/socket.py", line 530, in getaddrinfo
    for res in _socket.getaddrinfo(host, port, family, type, proto, flags):
socket.gaierror: [Errno -2] Name or service not known

During handling of the above exception, another exception occurred:

Traceback (most recent call last):
  File "/usr/lib/python3/dist-packages/requests/adapters.py", line 362, in send
    timeout=timeout
  File "/usr/lib/python3/dist-packages/urllib3/connectionpool.py", line 559, in urlopen
    _pool=self, _stacktrace=stacktrace)
  File "/usr/lib/python3/dist-packages/urllib3/util/retry.py", line 245, in increment
    raise six.reraise(type(error), error, _stacktrace)
  File "/usr/lib/python3/dist-packages/six.py", line 624, in reraise
    raise value.with_traceback(tb)
  File "/usr/lib/python3/dist-packages/urllib3/connectionpool.py", line 516, in urlopen
    body=body, headers=headers)
  File "/usr/lib/python3/dist-packages/urllib3/connectionpool.py", line 304, in _make_request
    self._validate_conn(conn)
  File "/usr/lib/python3/dist-packages/urllib3/connectionpool.py", line 724, in _validate_conn
    conn.connect()
  File "/usr/lib/python3/dist-packages/urllib3/connection.py", line 203, in connect
    conn = self._new_conn()
  File "/usr/lib/python3/dist-packages/urllib3/connection.py", line 133, in _new_conn
    (self.host, self.port), self.timeout, **extra_kw)
  File "/usr/lib/python3/dist-packages/urllib3/util/connection.py", line 64, in create_connection
    for res in socket.getaddrinfo(host, port, 0, socket.SOCK_STREAM):
  File "/usr/lib/python3.4/socket.py", line 530, in getaddrinfo
    for res in _socket.getaddrinfo(host, port, family, type, proto, flags):
urllib3.exceptions.ProtocolError: ('Connection aborted.', gaierror(-2, 'Name or service not known'))

During handling of the above exception, another exception occurred:

Traceback (most recent call last):
  File "/home/pi/fishtank/./fishtank_v4.py", line 404, in <module>
    main()
  File "/home/pi/fishtank/./fishtank_v4.py", line 366, in main
    dailylog()
  File "/home/pi/fishtank/./fishtank_v4.py", line 319, in dailylog
    aio.send(args.stream, deg_f)
  File "/usr/local/lib/python3.4/dist-packages/Adafruit_IO/client.py", line 90, in send
    return Data.from_dict(self._post(path, {'value': value}))
  File "/usr/local/lib/python3.4/dist-packages/Adafruit_IO/client.py", line 71, in _post
    data=json.dumps(data))
  File "/usr/lib/python3/dist-packages/requests/api.py", line 94, in post
    return request('post', url, data=data, json=json, **kwargs)
  File "/usr/lib/python3/dist-packages/requests/api.py", line 49, in request
    return session.request(method=method, url=url, **kwargs)
  File "/usr/lib/python3/dist-packages/requests/sessions.py", line 457, in request
    resp = self.send(prep, **send_kwargs)
  File "/usr/lib/python3/dist-packages/requests/sessions.py", line 569, in send
    r = adapter.send(request, **kwargs)
  File "/usr/lib/python3/dist-packages/requests/adapters.py", line 407, in send
    raise ConnectionError(err, request=request)
requests.exceptions.ConnectionError: ('Connection aborted.', gaierror(-2, 'Name or service not known'))
