sh: 1: modprobe: not found
sh: 1: modprobe: not found
--- Logging error ---
Traceback (most recent call last):
  File "/home/pi/fishtank/./fishtank_v3.py", line 416, in main
    with open('/dev/shm/mjpeg/user_annotate.txt', 'w') as f:
FileNotFoundError: [Errno 2] No such file or directory: '/dev/shm/mjpeg/user_annotate.txt'

During handling of the above exception, another exception occurred:

Traceback (most recent call last):
  File "/usr/lib/python3.5/logging/handlers.py", line 71, in emit
    if self.shouldRollover(record):
  File "/usr/lib/python3.5/logging/handlers.py", line 187, in shouldRollover
    msg = "%s\n" % self.format(record)
  File "/usr/lib/python3.5/logging/__init__.py", line 831, in format
    return fmt.format(record)
  File "/usr/lib/python3.5/logging/__init__.py", line 568, in format
    record.message = record.getMessage()
  File "/usr/lib/python3.5/logging/__init__.py", line 331, in getMessage
    msg = msg % self.args
TypeError: not all arguments converted during string formatting
Call stack:
  File "/home/pi/fishtank/./fishtank_v3.py", line 445, in <module>
    main()
  File "/home/pi/fishtank/./fishtank_v3.py", line 434, in main
    logger.info('program end:', sys.exc_info()[0])
Message: 'program end:'
Arguments: (<class 'FileNotFoundError'>,)

/home/pi/fishtank/   ***using directory***

