sh: 1: modprobe: not found
sh: 1: modprobe: not found
--- Logging error ---
Traceback (most recent call last):
  File "/home/pi/fishtank/./fishtank_v2.py", line 383, in main
    deg_c, deg_f, status = read_temp()
  File "/home/pi/fishtank/./fishtank_v2.py", line 232, in read_temp
    lines = read_temp_raw()
  File "/home/pi/fishtank/./fishtank_v2.py", line 222, in read_temp_raw
    stderr=subprocess.PIPE)
  File "/usr/lib/python3.4/subprocess.py", line 859, in __init__
    restore_signals, start_new_session)
  File "/usr/lib/python3.4/subprocess.py", line 1395, in _execute_child
    restore_signals, start_new_session, preexec_fn)
OSError: [Errno 12] Cannot allocate memory

During handling of the above exception, another exception occurred:

Traceback (most recent call last):
  File "/usr/lib/python3.4/logging/handlers.py", line 71, in emit
    if self.shouldRollover(record):
  File "/usr/lib/python3.4/logging/handlers.py", line 187, in shouldRollover
    msg = "%s\n" % self.format(record)
  File "/usr/lib/python3.4/logging/__init__.py", line 828, in format
    return fmt.format(record)
  File "/usr/lib/python3.4/logging/__init__.py", line 565, in format
    record.message = record.getMessage()
  File "/usr/lib/python3.4/logging/__init__.py", line 328, in getMessage
    msg = msg % self.args
TypeError: not all arguments converted during string formatting
Call stack:
  File "/home/pi/fishtank/./fishtank_v2.py", line 414, in <module>
    main()
  File "/home/pi/fishtank/./fishtank_v2.py", line 404, in main
    logger.info('program end:', sys.exc_info()[0])
Message: 'program end:'
Arguments: (<class 'OSError'>,)

/home/pi/fishtank/   ***using directory***

